<?xml version="1.0"?>
<robot name="mrl">
  

<link name="base_link">
    <visual>
      <geometry>
        <cylinder length="0.127" radius="0.25"/>
      </geometry>
     <material name="white">
        <color rgba="1 1 1 1"/>
      </material>
    </visual>

    <collision>
      <geometry>
        <cylinder length="0.19" radius="0.25"/>
      </geometry>
    </collision>

    <inertial>
      <mass value="3.6"/>
      <inertia ixx="0.4" ixy="0.0" ixz="0.0" iyy="0.4" iyz="0.0" izz="0.2"/>
    </inertial>

  </link>

<!--left wheel-->
<link name="left_wheel">
    <visual>
      <geometry>
        <cylinder length="0.05" radius="0.08"/>
      </geometry>
	<origin rpy="0 1.57 0" xyz="0 0 0"/>
     <material name="black">
        <color rgba="0 0 0 1"/>
      </material>
    </visual>
  </link>

  <joint name="left_wheel_joint" type="continuous">
  <axis xyz="1 0 0"/>
    <parent link="base_link"/>
    <child link="left_wheel"/>
     <origin xyz="0.15 0 -0.05"/>
  </joint>

<!--right wheel-->
<link name="right_wheel">
    <visual>
      <geometry>
        <cylinder length="0.05" radius="0.08"/>
      </geometry>
	<origin rpy="0 1.57 0" xyz="0 0 0"/>
    <material name="black"/>
    </visual>
  </link>

  <joint name="right_wheel_joint" type="continuous">
  <axis xyz="1 0 0"/>
    <parent link="base_link"/>
    <child link="right_wheel"/>
     <origin xyz="-0.15 0 -0.05"/>
  </joint>


<!--hokuyo laser-->
  <link name="hokuyo_link">
    <visual>
    <geometry>
        <mesh filename="package://mrl1_description/meshes/hokuyo.dae"/>
      </geometry>
    <origin xyz="0 0 0" rpy="0 0 0"/>
    <material name="blue"/>
    <color rgba="0 0 0.8 1"/>

    </visual>


    <collision>
      <origin xyz="0 0 0" rpy="0 0 0"/>
      <geometry>
	<box size="0.06 0.06 0.06"/>
      </geometry>
    </collision>

    <inertial>
      <mass value="1e-5" />
      <origin xyz="0 0 0" rpy="0 0 0"/>
      <inertia ixx="1e-6" ixy="0" ixz="0" iyy="1e-6" iyz="0" izz="1e-6" />
    </inertial>
  </link>

  <joint name="hokuyo_joint" type="fixed">
    <origin xyz="0 0.2 0.06" rpy="0 0 0"/>
    <parent link="base_link"/>
    <child link="hokuyo_link"/>
  </joint>


<!--Transmission to left motor-->
<transmission name="tran1">
    <type>transmission_interface/SimpleTransmission</type>
    <joint name="left_wheel_joint"/>
    <actuator name="left_motor">
      <hardwareInterface>EffortJointInterface</hardwareInterface>
      <mechanicalReduction>1</mechanicalReduction>
    </actuator>
  </transmission>

<!--Transmission to right motor-->
<transmission name="tran1">
    <type>transmission_interface/SimpleTransmission</type>
    <joint name="left_wheel_joint"/>
    <actuator name="left_motor">
      <hardwareInterface>EffortJointInterface</hardwareInterface>
      <mechanicalReduction>1</mechanicalReduction>
    </actuator>
  </transmission>

</robot>































